Workbook

Sheet Executive Summary
A1: WEBERBER MADRID - BUSINESS PLAN
A2: Physical Store - Moroccan Artisan Products
A3: Date: April 2026
A5: CONCEPT
A6: Weberber Madrid is a retail store specializing in authentic Moroccan artisan products:
A7: - Brass & copper hardware (hooks, knobs, towel racks - small items only)
A8: - Moroccan leather poufs (signature item)
A9: - Olive wood kitchenware (volume driver)
A10: - Traditional tea sets, lighting, decorative items
A12: REALISTIC YEAR-BY-YEAR FINANCIAL OVERVIEW
A13: Metric | B13: Year 1 (ramp-up) | C13: Year 2 (growth) | D13: Year 3 (mature)
A14: Annual Revenue | B14: ='Monthly Revenue Projection'!N10 -> 110450 | C14: =B14*1.75 -> 193287.5 | D14: =C14*1.4 -> 270602.5
A15: Items Sold | B15: ='Monthly Revenue Projection'!N5 -> 1275 | C15: =B15*1.6 -> 2040 | D15: =C15*1.3 -> 2652
A16: Avg Ticket | B16: 70 | C16: 75 | D16: 80
A17: Coefficient on Purchase | B17: 4.5 | C17: 5.5 | D17: 6.5
A18: Gross Margin % | B18: 0.65 | C18: 0.72 | D18: 0.79
A19: COGS + Transport + Duty | B19: =B14*0.35 -> 38657.5 | C19: =B16*1.4 -> 98 | D19: =C16*1.25 -> 93.75
A20: Annual Fixed Costs (incl. marketing) | B20: ='Fixed Costs - Madrid'!C34+'Monthly Revenue Projection'!N24 -> 56120 | C20: =B19*1.15 -> 44456.125 | D20: =C19*1.1 -> 107.8
A21: Net Profit (before tax) | B21: =B14-B18-B19 -> 71791.85 | C21: =C14-C18-C19 -> 193188.78 | D21: =D14-D18-D19 -> 270507.96
A22: Net Margin % | B22: =B20/B14 -> 0.50810321 | C22: =C20/C14 -> 0.23 | D22: =D20/D14 -> 0.0003983703
A24: KEY ASSUMPTIONS
A25: • Conservative coefficient progression (4.5 → 5.5 → 6.5) reflects buying power growth
A26: • Avg ticket starts at 75€ (real customer mix) and grows with brand reputation
A27: • Y1 = ramp-up phase with low foot traffic; Y2-Y3 = reputation + repeat customers
A28: • Marketing budget: 5,300€ Y1, growing with revenue to ~10K€ Y3
A29: • Owner-operated throughout (no employees) - ceiling on operating hours
A30: • Add employees in Y3 if revenue exceeds 200K€ to scale further
A32: STRATEGY NOTE: HIGH-TICKET BRASS EXCLUDED FROM STORE STOCK
A33: Faucets, sinks, showers, bathtubs (300-5000€) are excluded from physical store calculations.
A34: These items don't sell well as walk-in retail (designer/B2B/online channel only).
A35: Keeping them frees up capital and shelf space for high-turnover impulse items.

Sheet P&L Projection
A1: PROFIT & LOSS PROJECTION (3 YEARS)
B3: Year 1 | C3: Year 2 | D3: Year 3
A4: REVENUE
A5: Monthly avg revenue | B5: ='Monthly Revenue Projection'!N10/12 -> 9204.1667 | C5: =B5*1.75 -> 16107.292 | D5: =C5*1.4 -> 22550.208
A6: Growth assumption | B6: Ramp-up Y1 | C6: 0.75 | D6: 0.4
A7: Annual Revenue | B7: ='Monthly Revenue Projection'!N10 -> 110450 | C7: =B7*1.75 -> 193287.5 | D7: =C7*1.4 -> 270602.5
A9: COST OF GOODS SOLD
A10: COGS (purchase cost) | B10: =B7/4.5 -> 24544.444 | C10: =C7/5.5 -> 35143.182 | D10: =D7/6.5 -> 41631.154
A11: Transport & Import (~6-8% of revenue) | B11: =B7*0.08 -> 8836 | C11: =C7*0.07 -> 13530.125 | D11: =D7*0.06 -> 16236.15
A12: Import Duties (est. 2%) | B12: =B10*0.02 -> 490.88889 | C12: =C10*0.02 -> 702.86364 | D12: =D10*0.02 -> 832.62308
A13: Total COGS | B13: =B10+B11+B12 -> 33871.333 | C13: =C10+C11+C12 -> 49376.17 | D13: =D10+D11+D12 -> 58699.927
A15: GROSS PROFIT | B15: =B7-B13 -> 76578.667 | C15: =C7-C13 -> 143911.33 | D15: =D7-D13 -> 211902.57
A16: Gross Margin % | B16: =B15/B7 -> 0.69333333 | C16: =C15/C7 -> 0.74454545 | D16: =D15/D7 -> 0.78307692
A18: OPEX
A19: OPEX per year (incl. marketing) | B19: ='Fixed Costs - Madrid'!C34+'Monthly Revenue Projection'!N24 -> 56120 | C19: =B19*1.15 -> 64538 | D19: =C19*1.1 -> 70991.8
A20: OPEX growth | B20: Y1 base | C20: 0.15 | D20: 0.1
A21: EBITDA | B21: =B15-B19 -> 20458.667 | C21: =C15-C19 -> 79373.33 | D21: =D15-D19 -> 140910.77
A22: EBITDA Margin % | B22: =B21/B7 -> 0.18523012 | C22: =C21/C7 -> 0.41064906 | D22: =D21/D7 -> 0.52072975
A24: Store Fit-out Amortization | B24: 6000 | C24: 6000 | D24: 3000
A26: PROFIT BEFORE TAX | B26: =B21-B24 -> 14458.667 | C26: =C21-C24 -> 73373.33 | D26: =D21-D24 -> 137910.77
A27: Corporate Tax (15% Y1-Y2, 25% Y3) | B27: =B26*0.15 -> 2168.8 | C27: =C26*0.15 -> 11005.999 | D27: =D26*0.25 -> 34477.693
A29: NET PROFIT | B29: =B26-B27 -> 12289.867 | C29: =C26-C27 -> 62367.33 | D29: =D26-D27 -> 103433.08
A30: Net Margin % | B30: =B29/B7 -> 0.11127086 | C30: =C29/C7 -> 0.32266613 | D30: =D29/D7 -> 0.38223254

Sheet Break-Even Analysis
A1: BREAK-EVEN ANALYSIS (based on real costs)
A3: VARIABLE COSTS PER ITEM
A4: Average selling price per item | B4: 120 | D4: Weighted avg across all categories
A5: Average purchase cost (coef 7.5) | B5: =B4/7.5 -> 16 | D5: What we pay in Morocco
A6: Transport cost per item (est.) | B6: 5 | D6: ~10,000€/year for ~2,000 items
A7: Import duty per item (~2%) | B7: =B5*0.02 -> 0.32 | D7: EU-Morocco FTA preferential rate
A8: Total variable cost per item | B8: =B5+B6+B7 -> 21.32 | D8: Purchase + transport + duty
A9: Contribution margin per item | B9: =B4-B8 -> 98.68 | D9: Selling price - variable costs
A10: Contribution margin % | B10: =B9/B4 -> 0.82233333 | D10: Very high thanks to direct sourcing
A12: FIXED COSTS (from your real data)
A13: Monthly fixed costs | B13: ='Fixed Costs - Madrid'!B34 -> 4035 | D13: From Fixed Costs sheet
A14: Annual fixed costs | B14: ='Fixed Costs - Madrid'!C34 -> 49820 | D14: Monthly * 12
A16: BREAK-EVEN CALCULATION
A17: Monthly units to break even | B17: =B13/B9 -> 40.889745 | D17: Monthly fixed / contribution margin per unit
A18: Monthly revenue to break even | B18: =B17*B4 -> 4906.7694 | D18: Units * avg selling price
A19: Daily revenue to break even (26 days/mo) | B19: =B17/26 -> 1.5726825 | D19: Monthly / 26 working days
A20: Daily units to break even | B20: =B15/26 -> 0 | D20: Very achievable target
A21: Annual revenue to break even | B21: =B15*12 -> 0 | D21: Monthly * 12
A23: SCENARIOS
A24: Scenario | B24: Monthly Revenue | C24: Monthly Profit | D24: Annual Profit
A25: Pessimistic (10K/mo) | B25: 10000 | C25: =B25-(B25/7.5)-(B25*0.04)-'Fixed Costs - Madrid'!B34 -> 4231.6667 | D25: =C25*12 -> 50780
A26: Conservative (15K/mo) | B26: 15000 | C26: =B26-(B26/7.5)-(B26*0.04)-'Fixed Costs - Madrid'!B34 -> 8365 | D26: =C26*12 -> 100380
A27: Target Y1 (20K/mo) | B27: 20000 | C27: =B27-(B27/7.5)-(B27*0.04)-'Fixed Costs - Madrid'!B34 -> 12498.333 | D27: =C27*12 -> 149980
A28: Growth Y2 (30K/mo) | B28: 30000 | C28: =B28-(B28/7.5)-(B28*0.04)-'Fixed Costs - Madrid'!B34 -> 20765 | D28: =C28*12 -> 249180
A29: Mature Y3 (40K/mo) | B29: 40000 | C29: =B29-(B29/7.5)-(B29*0.04)-'Fixed Costs - Madrid'!B34 -> 29031.667 | D29: =C29*12 -> 348380
A31: PAYBACK PERIOD
A32: Initial Investment (from Investment sheet) | B32: ='Initial Investment'!B35 -> 29840 | D32: Total startup cost
A33: Avg monthly net profit (Y1 target) | B33: =C27 -> 12498.333 | D33: At 20K/mo revenue scenario
A34: Estimated payback period (months) | B34: =B32/B33 -> 2.3875183 | D34: Months to recover investment

Sheet Product Catalog & Costs
A1: COMPETITOR PRODUCT ANALYSIS & ESTIMATED COSTS
A3: Category | B3: Product Name | C3: Competitor Price (USD) | D3: Competitor Price (EUR) | E3: Est. Purchase Cost (Coef 6) | F3: Est. Purchase Cost (Coef 7.5) | G3: Est. Purchase Cost (Coef 9) | H3: Our Selling Price (Coef 5) | I3: Margin (Coef 5) | J3: Source
A4: Faucets | B4: Unlacquered Brass Kitchen Faucet | C4: 457.8 | D4: 421.176 | E4: 70.196 | F4: 56.1568 | G4: 46.797333 | H4: 357.9996 | I4: =H4-F4 -> 301.8428 | J4: Brasspure
A5: Faucets | B5: Solid Brass Three Holes Faucet with Lever Handle | C5: 450 | D5: 414 | E5: 69 | F5: 55.2 | G5: 46 | H5: 351.9 | I5: =H5-F5 -> 296.7 | J5: Brasspure
A6: Faucets | B6: Moroccan Copper Bridge Faucet Kitchen Faucets | C6: 440.2 | D6: 404.984 | E6: 67.497333 | F6: 53.997867 | G6: 44.998222 | H6: 344.2364 | I6: =H6-F6 -> 290.23853 | J6: Brasspure
A7: Other Brass | B7: Unlacquered Brass Pot Filler | C7: 440 | D7: 404.8 | E7: 67.466667 | F7: 53.973333 | G7: 44.977778 | H7: 344.08 | I7: =H7-F7 -> 290.10667 | J7: Brasspure
A8: Faucets | B8: Unlacquered Brass Bridge Faucet | C8: 437.9 | D8: 402.868 | E8: 67.144667 | F8: 53.715733 | G8: 44.763111 | H8: 342.4378 | I8: =H8-F8 -> 288.72207 | J8: Brasspure
A9: Faucets | B9: Unlacquered Brass Deck Mounted Faucet Wheel Handle | C9: 437 | D9: 402.04 | E9: 67.006667 | F9: 53.605333 | G9: 44.671111 | H9: 341.734 | I9: =H9-F9 -> 288.12867 | J9: Brasspure
A10: Faucets | B10: Unlacquered Brass Vanity Faucet | C10: 435.55 | D10: 400.706 | E10: 66.784333 | F10: 53.427467 | G10: 44.522889 | H10: 340.6001 | I10: =H10-F10 -> 287.17263 | J10: Brasspure
A11: Faucets | B11: Solid Brass Bridge Faucet Nickel Matte Finish | C11: 435.15 | D11: 400.338 | E11: 66.723 | F11: 53.3784 | G11: 44.482 | H11: 340.2873 | I11: =H11-F11 -> 286.9089 | J11: Brasspure
A12: Faucets | B12: Unlacquered Brass Kitchen Faucet | C12: 430 | D12: 395.6 | E12: 65.933333 | F12: 52.746667 | G12: 43.955556 | H12: 336.26 | I12: =H12-F12 -> 283.51333 | J12: Brasspure
A13: Faucets | B13: Unlacquered Brass Deck Mounted Sink Faucet | C13: 430 | D13: 395.6 | E13: 65.933333 | F13: 52.746667 | G13: 43.955556 | H13: 336.26 | I13: =H13-F13 -> 283.51333 | J13: Brasspure
A14: Faucets | B14: Unlacquered Brass Pot Filler Kitchen Faucet | C14: 430 | D14: 395.6 | E14: 65.933333 | F14: 52.746667 | G14: 43.955556 | H14: 336.26 | I14: =H14-F14 -> 283.51333 | J14: Brasspure
A15: Faucets | B15: Unlacquered Brass Bridge Kitchen Faucet | C15: 430 | D15: 395.6 | E15: 65.933333 | F15: 52.746667 | G15: 43.955556 | H15: 336.26 | I15: =H15-F15 -> 283.51333 | J15: Brasspure
... A282: Kitchen/Wood | B282: Round Trivet Handcrafted From Olive Wood | C282: 16.95 | D282: 15.594 | E282: 2.599 | F282: 2.0792 | G282: 1.7326667 | H282: 13.2549 | I282: =H282-F282 -> 11.1757 | J282: Beldinest

Sheet Category Summary
A1: PRODUCT CATEGORY SUMMARY
A3: Category | B3: # Products | C3: Avg Competitor Price (EUR) | D3: Est. Cost (Coef 7.5) | E3: Our Selling Price | F3: Gross Margin | G3: Suggested Initial Stock | H3: Initial Stock Investment | I3: Expected Monthly Revenue
A4: Chess | B4: 3 | C4: 119.5908 | D4: 15.94544 | E4: 101.65218 | F4: 0.84313725 | G4: 5 | H4: =G4*D4 -> 79.7272 | I4: =(E4*G4)-H4 -> 428.5337
A5: Faucets | B5: 73 | C5: 317.19193 | D5: 42.292257 | E5: 269.61314 | F5: 0.84313725 | G5: 15 | H5: =G5*D5 -> 634.38386 | I5: =(E5*G5)-H5 -> 3409.8132
A6: Hardware | B6: 18 | C6: 99.7648 | D6: 13.301973 | E6: 84.80008 | F6: 0.84313725 | G6: 30 | H6: =G6*D6 -> 399.0592 | I6: =(E6*G6)-H6 -> 2144.9432
A7: Kitchen/Wood | B7: 101 | C7: 57.686642 | D7: 7.6915522 | E7: 49.033645 | F7: 0.84313725 | G7: 40 | H7: =G7*D7 -> 307.66209 | I7: =(E7*G7)-H7 -> 1653.6837
A8: Other Brass | B8: 17 | C8: 450.40927 | D8: 60.054569 | E8: 382.84788 | F8: 0.84313725 | G8: 5 | H8: =G8*D8 -> 300.27285 | I8: =(E8*G8)-H8 -> 1613.9666
A9: Poufs | B9: 32 | C9: 257.554 | D9: 34.340533 | E9: 218.9209 | F9: 0.84313725 | G9: 20 | H9: =G9*D9 -> 686.81067 | I9: =(E9*G9)-H9 -> 3691.6073
A10: Showers | B10: 17 | C10: 363.40054 | D10: 48.453405 | E10: 308.89046 | F10: 0.84313725 | G10: 8 | H10: =G10*D10 -> 387.62724 | I10: =(E10*G10)-H10 -> 2083.4964
A11: Sink Acc. | B11: 5 | C11: 118.45184 | D11: 15.793579 | E11: 100.68406 | F11: 0.84313725 | G11: 15 | H11: =G11*D11 -> 236.90368 | I11: =(E11*G11)-H11 -> 1273.3573
A12: Sinks | B12: 16 | C12: 210.81915 | D12: 28.10922 | E12: 179.19628 | F12: 0.84313725 | G12: 6 | H12: =G12*D12 -> 168.65532 | I12: =(E12*G12)-H12 -> 906.52234
A13: Tea & Glass | B13: 18 | C13: 118.58289 | D13: 15.811052 | E13: 100.79546 | F13: 0.84313725 | G13: 25 | H13: =G13*D13 -> 395.2763 | I13: =(E13*G13)-H13 -> 2124.6101
A15: TOTAL | G15: =SUM(G4:G13) -> 169 | H15: =SUM(H4:H13) -> 3596.3784 | I15: =SUM(I4:I13) -> 19330.534

Sheet Fixed Costs - Madrid
A1: FIXED COSTS - PHYSICAL STORE IN MADRID
A3: Cost Item | B3: Monthly (EUR) | C3: Annual (EUR) | D3: Notes
A4: RENT & PREMISES
A5: Store Rent (60-80m2, central Madrid) | B5: 2100 | C5: =B5*12 -> 25200 | D5: Malasaña/Chueca/Salamanca area
A6: Security Deposit (2 months) | C6: =B5*2 -> 4200 | D6: One-time, refundable
A7: Store Insurance | B7: 30 | C7: =B7*12 -> 360 | D7: Civil liability + stock coverage
A8: Utilities (electricity, water, gas) | B8: 100 | C8: =B8*12 -> 1200 | D8: Includes lighting/display
A9: Internet & Phone | B9: 15 | C9: =B9*12 -> 180 | D9: Fiber + business line
A11: LABOR COSTS
A12: Store Manager (full-time) | B12: 1300 | C12: =B12*14 -> 18200 | D12: 14 pays/year (Spain), gross salary
A13: Sales Associate (full-time) | B13: 0 | C13: =B13*14 -> 0 | D13: 14 pays/year, gross salary
A14: Social Security - Manager (30%) | B14: =B12*0.3 -> 390 | C14: =B14*12 -> 4680 | D14: Employer SS contribution ~30%
A15: Social Security - Associate (30%) | B15: =B13*0.3 -> 0 | C15: =B15*12 -> 0 | D15: Employer SS contribution ~30%
A16: Autónomo (owner's SS) | B16: 0 | C16: =B16*12 -> 0 | D16: Self-employed social security (min base 2026)
A18: TAXES & LEGAL (SPAIN)
A19: IVA (VAT) - 21% on sales | B19: Variable | C19: Variable | D19: 21% standard rate - collected on sales, deducted on purchases
A20: Import Duty (Morocco to EU) | D20: 0-6.5% depending on product (EU-Morocco FTA)
A21: Customs clearance fees | D21: Per shipment ~200-300€, est. 4-6 shipments/year
A22: Corporate Tax (Impuesto de Sociedades) | D22: 25% on profits (15% first 2 years for new companies)
A23: Gestoría (accounting/tax filing) | B23: 50 | C23: =B23*12 -> 600 | D23: Monthly bookkeeping + quarterly VAT/tax filing
A24: Business License (Licencia de Apertura) | C24: 1000 | D24: One-time, Madrid municipality
A25: (Company Registration) | C25: 400 | D25: One-time, notary + registration
A27: MARKETING & OTHER
A28: Website & E-commerce maintenance | B28: 0 | C28: =B28*12 -> 0 | D28: Hosting, updates, SEO
A29: Social Media & Marketing | B29: 0 | C29: =B29*12 -> 0 | D29: Instagram, Google Ads, local events
A30: Store Design & Fit-out (amortized) | B30: 0 | C30: =B30*12 -> 0 | D30: Total ~15,000€ amortized over 2.5 years
A31: POS System & Software | B31: 0 | C31: =B31*12 -> 0 | D31: Point of sale + inventory management
A32: Packaging & Supplies | B32: 50 | C32: =B32*12 -> 600 | D32: Bags, wrapping, business cards
A34: TOTAL MONTHLY FIXED COSTS | B34: =SUM(B5:B32) -> 4035 | C34: =(B34*12)+SUM(C24:C25) -> 49820 | D34: Excludes variable costs (COGS, IVA, corporate tax)

Sheet Transport & Import
A1: TRANSPORTATION & IMPORT COSTS (MOROCCO → MADRID)
A3: Item | B3: Cost (EUR) | C3: Notes
A4: OPTION A: PALLET FREIGHT (per shipment, ~500kg)
A5: Moroccan inland transport (Marrakech/Fez → Tangier) | B5: 300 | C5: Truck transport to port
A6: Tangier → Algeciras ferry (freight) | B6: 450 | C6: Ro-Ro ferry, ~1h crossing
A7: Algeciras → Madrid road transport | B7: 600 | C7: ~650km truck
A8: Customs broker - Morocco export | B8: 200 | C8: Export documentation
A9: Customs broker - Spain import | B9: 250 | C9: Import declaration, IVA deferral
A10: Phytosanitary certificate (wood items) | B10: 100 | C10: Required for olive wood
A11: EUR.1 Certificate of Origin | B11: 50 | C11: For preferential tariff treatment
A12: Subtotal per pallet shipment | B12: 1950 | C12: Before product duty
A14: OPTION B: 20FT CONSOLIDATED CONTAINER
A15: Door-to-door container Morocco → Madrid | B15: 2800 | C15: Includes all transport legs
A16: Customs & documentation (all-in) | B16: 500 | C16: Brokerage bundle
A17: Subtotal per container (20ft, ~10-15 m³) | B17: 3300 | C17: Better unit economics
A19: ANNUAL TRANSPORT BUDGET (Y1)
A20: Scenario A: 6 pallet shipments/year | B20: 11700 | C20: Frequent, smaller restocks
A21: Scenario B: 3 containers/year | B21: 9900 | C21: Larger, less frequent
A22: RECOMMENDED Y1 BUDGET | B22: 10000 | C22: Mix: 2 containers + 2 pallets
A23: Annual transport % of revenue | B23: =B22/'Monthly Revenue Projection'!N8 -> #DIV/0! | C23: ≈4% of revenue
A25: IMPORT DUTY DETAILS (EU-Morocco FTA)
A26: Brass/copper articles (HS 7418/7419) | B26: 0-3% | C26: Most qualify for 0% w/ EUR.1
A27: Leather goods - poufs (HS 4205) | B27: 1.7-3% | C27: Reduced rate
A28: Wood articles (HS 4419/4420) | B28: 0-3% | C28: Olive wood kitchenware
A29: Glass articles - tea glasses (HS 7013) | B29: 0-6.5% | C29: Some duty applies
A30: Ceramic/pottery (HS 6913/6914) | B30: 0-6% | C30: Decorative items
A31: Average effective duty rate | B31: ~2% | C31: Used in P&L projections

Sheet Initial Investment
A1: INITIAL INVESTMENT REQUIRED
A3: Item | B3: Amount (EUR) | C3: Notes
A4: LEGAL & SETUP
A5: Company Registration (SL) | B5: 100 | C5: Notary + Registro Mercantil
A6: Business License (Licencia de Apertura) | B6: 1000 | C6: Madrid municipality
A7: Legal fees / Lawyer | B7: 300 | C7: Optional - can use gestoría package instead
B8: =SUM(B5:B7) -> 1400
A9: PREMISES
A10: Security Deposit (2 months rent) | B10: ='Fixed Costs - Madrid'!B5*2 -> 4200 | C10: Refundable - 2 months of real rent
A11: First Month Rent | B11: ='Fixed Costs - Madrid'!B5 -> 2100 | C11: First month rent
A12: Store Renovation & Design | B12: 2000 | C12: Lean Moroccan-themed fit-out, used display units
A13: Signage & Branding | B13: 200 | C13: Exterior sign, window graphics
A14: Lighting & Fixtures | B14: 500 | C14: Spotlights, display lighting
A16: INVENTORY
A17: Initial Stock - Brass Hardware (small items) | B17: 500 | C17: ~30 items: hooks, knobs, towel racks, sink accessories (avg cost 22€)
A18: Initial Stock - Leather Poufs | B18: 200 | C18: ~20 poufs at ~49€ cost (coef 4.5)
A19: Initial Stock - Kitchen & Olive Wood | B19: 500 | C19: ~80 items, avg cost 11€ (volume driver)
A20: Initial Stock - Tea, Chess & Decor | B20: 500 | C20: ~30 items mixed (tea sets, chess, lanterns)
A21: First Shipment Transport | B21: 600 | C21: First container/pallet from Morocco
A23: TECHNOLOGY & EQUIPMENT
A24: POS System & Hardware | B24: 200 | C24: Tablet-based POS (Square/Sumup), card reader, receipt printer
A25: Security System & CCTV | B25: 300 | C25: Alarm + cameras
A26: Computer & Software | B26: 0 | C26: Inventory mgmt, accounting
A28: MARKETING LAUNCH
A29: Brand Identity & Website Update | B29: 0 | C29: Madrid-specific pages, Google Business
A30: Opening Campaign | B30: 500 | C30: Opening event + first 2 weeks paid social
A32: WORKING CAPITAL
A33: Cash Reserve (3 months operating) | B33: ='Fixed Costs - Madrid'!B34*4 -> 16140 | C33: 4 months of fixed costs
A35: TOTAL INITIAL INVESTMENT | B35: =SUM(B5:B7,B10:B14,B17:B21,B24:B26,B29:B30,B33) -> 29840
A37: SECTION TOTALS
A38: Legal & Setup | B38: =SUM(B5:B7) -> 1400
A39: Premises | B39: =SUM(B10:B14) -> 9000
A40: Initial Inventory | B40: =SUM(B17:B21) -> 2300
A41: Technology & Equipment | B41: =SUM(B24:B26) -> 500
A42: Marketing Launch | B42: =SUM(B29:B30) -> 500
A43: Working Capital | B43: =B33 -> 16140
A44: TOTAL | B44: =SUM(B38:B43) -> 29840
A46: NOTES
A47: • Stock revised: NO high-ticket brass (faucets/sinks/showers/bathtubs) in store
A48: • Inventory cost ~5,300€ vs 13,100€ in old plan — frees up ~8K€ of capital
...

Sheet Spain Tax Reference
A1: SPAIN / MADRID TAX REFERENCE FOR RETAIL BUSINESS
A3: Tax / Obligation | B3: Rate / Amount | C3: Details
A4: IVA (VAT) | B4: 21% | C4: Standard rate on all sales. Charged to customers, remitted quarterly (Modelo 303). Input VAT on purchases is deductible.
A5: IVA Reduced Rate | B5: 10% | C5: Applies to some food items - may apply to olive wood kitchenware used with food (consult gestor).
A6: Corporate Tax (Impuesto Sociedades) | B6: 25% | C6: Standard rate. NEW companies: 15% for first 2 profitable years (since 2015 reform).
A7: IRPF (if sole proprietor) | B7: 19-47% | C7: Progressive income tax if operating as autónomo instead of SL. Quarterly payments (Modelo 130).
A8: Social Security - Employer | B8: ~30% | C8: Employer pays ~30% on top of gross salary for each employee. Covers healthcare, pension, unemployment.
A9: Social Security - Autónomo | B9: ~350€/month | C9: Self-employed contribution (2026 est). Base ~1,300€/month, rate ~30.6%. Flat rate 80€/month first year available.
A10: IAE (Business Activity Tax) | B10: Exempt <1M€ | C10: Exempt for businesses with turnover under 1 million euros.
A11: IBI (Property Tax) | B11: Paid by landlord | C11: Included in rent typically. If you own, ~0.4-1.1% of cadastral value.
A12: Modelo 347 (Annual) | B12: Reporting | C12: Annual declaration of operations >3,005.06€ with any single party.
A13: Modelo 349 (Quarterly) | B13: Reporting | C13: Intra-EU operations reporting (if selling to other EU countries).
A14: Customs Duty (Morocco imports) | B14: 0-6.5% | C14: EU-Morocco Association Agreement provides preferential rates. Need EUR.1 certificate.
A15: Withholding Tax on Rent | B15: 19% | C15: Landlord may require you to withhold 19% of rent and pay to Hacienda (Modelo 115).

Sheet Monthly Revenue Projection
A1: MONTHLY REVENUE PROJECTION - YEAR 1 (REALISTIC)
A2: Conservative ramp-up - high-ticket brass excluded (B2B/online only)
A4: Item | B4: M1 (Open) | C4: M2 | D4: M3 | E4: M4 | F4: M5 | G4: M6 (Summer) | H4: M7 (Tourist Peak) | I4: M8 | J4: M9 | K4: M10 | L4: M11 (BF) | M4: M12 (Xmas) | N4: TOTAL Y1
A5: Items Sold | B5: 35 | C5: 55 | D5: 75 | E5: 90 | F5: 100 | G5: 115 | H5: 140 | I5: 125 | J5: 95 | K5: 110 | L5: 150 | M5: 185 | N5: =SUM(B5:M5) -> 1275
A6: Items per Day (26 days) | B6: =B5/26 -> 1.3461538 | C6: =C5/26 -> 2.1153846 | D6: =D5/26 -> 2.8846154 | E6: =E5/26 -> 3.4615385 | F6: =F5/26 -> 3.8461538 | G6: =G5/26 -> 4.4230769 | H6: =H5/26 -> 5.3846154 | I6: =I5/26 -> 4.8076923 | ... M6: =M5/26 -> 7.1153846 | N6: =N5/(26*12) -> 4.0865385
A7: Avg Ticket per Item (€) | B7: 80 | C7: 81 | D7: 82 | E7: 83 | F7: 84 | G7: 85 | H7: 86 | I7: 87 | J7: 88 | K7: 89 | L7: 90 | M7: 91 | N7: 92
A9: REVENUE (€)
A10: Monthly Revenue | B10: =B5*B7 -> 2800 | C10: =C5*C7 -> 4455 | D10: =D5*D7 -> 6150 | E10: =E5*E7 -> 7470 | F10: =F5*F7 -> 8400 | G10: =G5*G7 -> 9775 | H10: =H5*H7 -> 12040 | I10: =I5*I7 -> 10875 | ... M10: =M5*M7 -> 16835 | N10: =SUM(B10:M10) -> 110450
A12: VARIABLE COSTS (Coefficient 4.5 - realistic for Y1)
A13: Purchase Cost (Coef 4.5) | B13: =B10/4.5 -> 622.22222 | C13: =C10/4.5 -> 990 | D13: =D10/4.5 -> 1366.6667 | E13: =E10/4.5 -> 1660 | F13: =F10/4.5 -> 1866.6667 | G13: =G10/4.5 -> 2172.2222 | H13: =H10/4.5 -> 2675.5556 | I13: =I10/4.5 -> 2416.6667 | ... M13: =M10/4.5 -> 3741.1111 | N13: =SUM(B13:M13) -> 24544.444
A14: Transport & Import (~8% of revenue) | B14: =B10*0.08 -> 224 | C14: =C10*0.08 -> 356.4 | D14: =D10*0.08 -> 492 | E14: =E10*0.08 -> 597.6 | F14: =F10*0.08 -> 672 | G14: =G10*0.08 -> 782 | H14: =H10*0.08 -> 963.2 | I14: =I10*0.08 -> 870 | ... M14: =M10*0.08 -> 1346.8 | N14: =SUM(B14:M14) -> 8836
A15: Import Duty (~2% of cost) | B15: =B13*0.02 -> 12.444444 | C15: =C13*0.02 -> 19.8 | D15: =D13*0.02 -> 27.333333 | E15: =E13*0.02 -> 33.2 | F15: =F13*0.02 -> 37.333333 | G15: =G13*0.02 -> 43.444444 | H15: =H13*0.02 -> 53.511111 | I15: =I13*0.02 -> 48.333333 | ... M15: =M13*0.02 -> 74.822222 | N15: =SUM(B15:M15) -> 490.88889
A16: Payment processing (1.5%) | B16: =B10*0.015 -> 42 | C16: =C10*0.015 -> 66.825 | D16: =D10*0.015 -> 92.25 | E16: =E10*0.015 -> 112.05 | F16: =F10*0.015 -> 126 | G16: =G10*0.015 -> 146.625 | H16: =H10*0.015 -> 180.6 | I16: =I10*0.015 -> 163.125 | ... M16: =M10*0.015 -> 252.525 | N16: =SUM(B16:M16) -> 1656.75
A17: Total Variable Costs | B17: =SUM(B13:B16) -> 900.66667 | C17: =SUM(C13:C16) -> 1433.025 | D17: =SUM(D13:D16) -> 1978.25 | E17: =SUM(E13:E16) -> 2402.85 | F17: =SUM(F13:F16) -> 2702 | G17: =SUM(G13:G16) -> 3144.2917 | H17: =SUM(H13:H16) -> 3872.8667 | I17: =SUM(I13:I16) -> 3498.125 | ... M17: =SUM(M13:M16) -> 5415.2583 | N17: =SUM(B17:M17) -> 35528.083
A19: GROSS PROFIT | B19: =B10-B17 -> 1899.3333 | C19: =C10-C17 -> 3021.975 | D19: =D10-D17 -> 4171.75 | E19: =E10-E17 -> 5067.15 | F19: =F10-F17 -> 5698 | G19: =G10-G17 -> 6630.7083 | H19: =H10-H17 -> 8167.1333 | I19: =I10-I17 -> 7376.875 | ... M19: =M10-M17 -> 11419.742 | N19: =SUM(B19:M19) -> 74921.917
A20: Gross Margin % | B20: =B19/B10 -> 0.67833333 | C20: =C19/C10 -> 0.67833333 | D20: =D19/D10 -> 0.67833333 | E20: =E19/E10 -> 0.67833333 | F20: =F19/F10 -> 0.67833333 | G20: =G19/G10 -> 0.67833333 | H20: =H19/H10 -> 0.67833333 | I20: =I19/I10 -> 0.67833333 | ... N20: =N19/N10 -> 0.67833333
A22: FIXED COSTS (€)
A23: Base Fixed Costs (from Fixed Costs sheet) | B23: ='Fixed Costs - Madrid'!B34 -> 4035 | C23: ='Fixed Costs - Madrid'!B34 -> 4035 | D23: ='Fixed Costs - Madrid'!B34 -> 4035 | E23: ='Fixed Costs - Madrid'!B34 -> 4035 | F23: ='Fixed Costs - Madrid'!B34 -> 4035 | G23: ='Fixed Costs - Madrid'!B34 -> 4035 | H23: ='Fixed Costs - Madrid'!B34 -> 4035 | I23: ='Fixed Costs - Madrid'!B34 -> 4035 | J23: ='Fixed Costs - Madrid'!B34 -> 4035 | K23: ='Fixed Costs - Madrid'!B34 -> 4035 | L23: ='Fixed Costs - Madrid'!B34 -> 4035 | M23: ='Fixed Costs - Madrid'!B34 -> 4035 | N23: ='Fixed Costs - Madrid'!B34*12 -> 48420
A24: Marketing (Recommended Budget) | B24: 800 | C24: 500 | D24: 400 | E24: 400 | F24: 400 | G24: 400 | H24: 400 | I24: 300 | J24: 400 | K24: 500 | L24: 800 | M24: 1000 | N24: 6300
A25: Total Fixed Costs | B25: =B23+B24 -> 4835 | C25: =C23+C24 -> 4535 | D25: =D23+D24 -> 4435 | E25: =E23+E24 -> 4435 | F25: =F23+F24 -> 4435 | G25: =G23+G24 -> 4435 | H25: =H23+H24 -> 4435 | I25: =I23+I24 -> 4335 | ... M25: =M23+M24 -> 5035 | N25: =SUM(B25:M25) -> 54720
A27: NET PROFIT (before tax) | B27: =B19-B25 -> -2935.6667 | C27: =C19-C25 -> -1513.025 | D27: =D19-D25 -> -263.25 | E27: =E19-E25 -> 632.15 | F27: =F19-F25 -> 1263 | G27: =G19-G25 -> 2195.7083 | H27: =H19-H25 -> 3732.1333 | I27: =I19-I25 -> 3041.875 | ... M27: =M19-M25 -> 6384.7417 | N27: =SUM(B27:M27) -> 20201.917
A28: Net Margin % | B28: =B27/B10 -> -1.0484524 | C28: =C27/C10 -> -0.33962402 | D28: =D27/D10 -> -0.042804878 | E28: =E27/E10 -> 0.084625167 | F28: =F27/F10 -> 0.15035714 | G28: =G27/G10 -> 0.22462489 | H28: =H27/H10 -> 0.30997785 | I28: =I27/I10 -> 0.27971264 | ... N28: =N27/N10 -> 0.18290554
A30: Cumulative Net Profit | B30: =B27 -> -2935.6667 | C30: =B30+C27 -> -4448.6917 | D30: =C30+D27 -> -4711.9417 | E30: =D30+E27 -> -4079.7917 | F30: =E30+F27 -> -2816.7917 | G30: =F30+G27 -> -621.08333 | H30: =G30+H27 -> 3111.05 | I30: =H30+I27 -> 6152.925 | J30: =I30+J27 -> 7388.7917 | ... M30: =L30+M27 -> 20201.917
A33: REVISED ASSUMPTIONS (HIGH-TICKET BRASS EXCLUDED)
A34: • Catalog: 177 retail-friendly items (faucets/sinks/showers/bathtubs removed)
A35: • Avg ticket: 70€ (blended weight: kitchen wood + tea + hardware + poufs)
A36: • Coefficient 4.5x on purchase price (conservative for new buyer)
A37: • Gross margin: ~67% after transport + duty + payment processing
A38: • Heavy focus on high-volume items: olive wood, tea glasses, hardware
A39: • Poufs are the main 'statement piece' - 3-4 sales/month
A40: • High-ticket brass kept for online/B2B channel (not in store stock)
A42: WHY THIS IS MORE REALISTIC:
A43: • Store traffic skews heavily toward small impulse purchases
A44: • Faucets/sinks need designer specifications - rarely walk-in sales
A45: • Inventory cost much lower (no 500€ items tied up on shelves)
... A50: • Y3: ~210K€ (+40%, mature operation, B2B online channel grows)

Sheet Sales Projection by Category
A1: SALES PROJECTION BY CATEGORY (corrected)
A2: Break-even uses TRUE margin (after purchase, transport, duty, payment processing)
A4: ASSUMPTIONS (edit here, all calcs update)
A5: Pricing discount vs competitor | B5: 0.15
A6: Coefficient on our purchase price | B6: 4.5
A7: Transport % of revenue | B7: 0.08
A8: Import duty % (on COGS) | B8: 0.02
A9: Payment processing % of revenue | B9: 0.015
A10: Monthly fixed costs (€) | B10: ='Fixed Costs - Madrid'!B34 -> 4035
A12: 1. CATEGORY BREAKDOWN
A14: Category | B14: # Ref. | C14: Avg Comp. Price (€) | D14: Our Price (competitor×(1-disc)) | E14: COGS (price/coef) | F14: Transport | G14: Duty | H14: Payment | I14: Total Var Cost | J14: TRUE Margin per Item | K14: Margin % | L14: Items/Month to Break Even | M14: % of Catalog
A15: Leather Poufs | B15: 32 | C15: 257.554 | D15: =C15*(1-$B$5) -> 218.9209 | E15: =D15/$B$6 -> 48.649089 | F15: =D15*$B$7 -> 17.513672 | G15: =E15*$B$8 -> 0.97298178 | H15: =D15*$B$9 -> 3.2838135 | I15: =E15+F15+G15+H15 -> 70.419556 | J15: =D15-I15 -> 148.50134 | K15: =J15/D15 -> 0.67833333 | L15: =$B$10/J15 -> 27.171471 | M15: 0.18079096
A16: Chess Sets | B16: 3 | C16: 119.5908 | D16: =C16*(1-$B$5) -> 101.65218 | E16: =D16/$B$6 -> 22.589373 | F16: =D16*$B$7 -> 8.1321744 | G16: =E16*$B$8 -> 0.45178747 | H16: =D16*$B$9 -> 1.5247827 | I16: =E16+F16+G16+H16 -> 32.698118 | J16: =D16-I16 -> 68.954062 | K16: =J16/D16 -> 0.67833333 | L16: =$B$10/J16 -> 58.51722 | M16: 0.016949153
A17: Tea Sets & Glasses | B17: 18 | C17: 118.58289 | D17: =C17*(1-$B$5) -> 100.79546 | E17: =D17/$B$6 -> 22.39899 | F17: =D17*$B$7 -> 8.0636364 | G17: =E17*$B$8 -> 0.4479798 | H17: =D17*$B$9 -> 1.5119318 | I17: =E17+F17+G17+H17 -> 32.422538 | J17: =D17-I17 -> 68.372917 | K17: =J17/D17 -> 0.67833333 | L17: =$B$10/J17 -> 59.014595 | M17: 0.10169492
A18: Sink Accessories | B18: 5 | C18: 118.45184 | D18: =C18*(1-$B$5) -> 100.68406 | E18: =D18/$B$6 -> 22.374236 | F18: =D18*$B$7 -> 8.0547251 | G18: =E18*$B$8 -> 0.44748473 | H18: =D18*$B$9 -> 1.510261 | I18: =E18+F18+G18+H18 -> 32.386707 | J18: =D18-I18 -> 68.297357 | K18: =J18/D18 -> 0.67833333 | L18: =$B$10/J18 -> 59.079885 | M18: 0.028248588
A19: Hardware & Accessories | B19: 18 | C19: 99.7648 | D19: =C19*(1-$B$5) -> 84.80008 | E19: =D19/$B$6 -> 18.844462 | F19: =D19*$B$7 -> 6.7840064 | G19: =E19*$B$8 -> 0.37688924 | H19: =D19*$B$9 -> 1.2720012 | I19: =E19+F19+G19+H19 -> 27.277359 | J19: =D19-I19 -> 57.522721 | K19: =J19/D19 -> 0.67833333 | L19: =$B$10/J19 -> 70.146195 | M19: 0.10169492
A20: Kitchen & Olive Wood | B20: 101 | C20: 57.686642 | D20: =C20*(1-$B$5) -> 49.033645 | E20: =D20/$B$6 -> 10.896366 | F20: =D20*$B$7 -> 3.9226916 | G20: =E20*$B$8 -> 0.21792731 | H20: =D20*$B$9 -> 0.73550468 | I20: =E20+F20+G20+H20 -> 15.772489 | J20: =D20-I20 -> 33.261156 | K20: =J20/D20 -> 0.67833333 | L20: =$B$10/J20 -> 121.31268 | M20: 0.57062147
A21: WEIGHTED AVG / TOTAL | B21: 177 | C21: 107.05858 | D21: =C21*(1-$B$5) -> 90.999794 | E21: =D21/$B$6 -> 20.222176 | F21: =D21*$B$7 -> 7.2799835 | G21: =E21*$B$8 -> 0.40444353 | H21: =D21*$B$9 -> 1.3649969 | I21: =E21+F21+G21+H21 -> 29.2716 | J21: =D21-I21 -> 61.728193 | K21: =J21/D21 -> 0.67833333 | L21: =$B$10/J21 -> 65.367214
A24: 2. PRICE RANGE BREAKDOWN
A26: Price Range (€) | B26: # Items | C26: % Catalog | D26: Avg Price | E26: Our Price | F26: Total Var Cost | G26: TRUE Margin | H26: Margin % | I26: Items/Mo BE | J26: Items/Day BE | K26: Typical Products
A27: 0 - 25€ | B27: 23 | C27: 0.1299435 | D27: 18.714 | E27: =D27*(1-$B$5) -> 15.9069 | F27: =E27/$B$6+E27*$B$7+E27/$B$6*$B$8+E27*$B$9 -> 5.1167195 | G27: =E27-F27 -> 10.79018 | H27: =G27/E27 -> 0.67833333 | I27: =$B$10/G27 -> 373.95111 | J27: =I27/26 -> 14.382735 | K27: Mini scoops, sauce dishes, small wood items
A28: 25 - 50€ | B28: 57 | C28: 0.3220339 | D28: 36.534491 | E28: =D28*(1-$B$5) -> 31.054318 | F28: =E28/$B$6+E28*$B$7+E28/$B$6*$B$8+E28*$B$9 -> 9.9891388 | G28: =E28-F28 -> 21.065179 | H28: =G28/E28 -> 0.67833333 | I28: =$B$10/G28 -> 191.54834 | J28: =I28/26 -> 7.3672438 | K28: Cutting boards, hooks, knobs, coasters
A29: 50 - 100€ | B29: 33 | C29: 0.18644068 | D29: 76.802715 | E29: =D29*(1-$B$5) -> 65.282308 | F29: =E29/$B$6+E29*$B$7+E29/$B$6*$B$8+E29*$B$9 -> 20.999142 | G29: =E29-F29 -> 44.283166 | H29: =G29/E29 -> 0.67833333 | I29: =$B$10/G29 -> 91.118147 | J29: =I29/26 -> 3.5045441 | K29: Bowls, mortars, towel racks, mid-size wood
A30: 100 - 200€ | B30: 23 | C30: 0.1299435 | D30: 153.1484 | E30: =D30*(1-$B$5) -> 130.17614 | F30: =E30/$B$6+E30*$B$7+E30/$B$6*$B$8+E30*$B$9 -> 41.873325 | G30: =E30-F30 -> 88.302815 | H30: =G30/E30 -> 0.67833333 | I30: =$B$10/G30 -> 45.695033 | J30: =I30/26 -> 1.7575013 | K30: Tea sets, chess, decorative items
A31: 200 - 350€ | B31: 41 | C31: 0.23163842 | D31: 253.16044 | E31: =D31*(1-$B$5) -> 215.18637 | F31: =E31/$B$6+E31*$B$7+E31/$B$6*$B$8+E31*$B$9 -> 69.218283 | G31: =E31-F31 -> 145.96809 | H31: =G31/E31 -> 0.67833333 | I31: =$B$10/G31 -> 27.643028 | J31: =I31/26 -> 1.0631934 | K31: Leather poufs, premium tea, large hardware
A34: 3. REALISTIC MONTHLY SALES MIX
A35: Steady-state target month (around M6-M7 in ramp-up). Edit 'Items/Month' to test scenarios.
A37: Category | B37: Avg Comp. Price | C37: Our Price | D37: TRUE Margin/ Item | E37: Items/Month | F37: Revenue/Month | G37: Margin Generated | H37: % Total Margin
A38: Kitchen & Olive Wood | B38: 57.686642 | C38: =B38*(1-$B$5) -> 49.033645 | D38: =C38-(C38/$B$6+C38*$B$7+C38/$B$6*$B$8+C38*$B$9) -> 33.261156 | E38: 60 | F38: =C38*E38 -> 2942.0187 | G38: =D38*E38 -> 1995.6694 | H38: =G38/G44 -> 0.40155599
A39: Tea Sets & Glasses | B39: 118.58289 | C39: =B39*(1-$B$5) -> 100.79546 | D39: =C39-(C39/$B$6+C39*$B$7+C39/$B$6*$B$8+C39*$B$9) -> 68.372917 | E39: 12 | F39: =C39*E39 -> 1209.5455 | G39: =D39*E39 -> 820.47501 | H39: =G39/G44 -> 0.1650908
A40: Hardware & Accessories | B40: 99.7648 | C40: =B40*(1-$B$5) -> 84.80008 | D40: =C40-(C40/$B$6+C40*$B$7+C40/$B$6*$B$8+C40*$B$9) -> 57.522721 | E40: 15 | F40: =C40*E40 -> 1272.0012 | G40: =D40*E40 -> 862.84081 | H40: =G40/G44 -> 0.17361538
A41: Sink Accessories | B41: 118.45184 | C41: =B41*(1-$B$5) -> 100.68406 | D41: =C41-(C41/$B$6+C41*$B$7+C41/$B$6*$B$8+C41*$B$9) -> 68.297357 | E41: 5 | F41: =C41*E41 -> 503.42032 | G41: =D41*E41 -> 341.48678 | H41: =G41/G44 -> 0.068711814
A42: Leather Poufs | B42: 257.554 | C42: =B42*(1-$B$5) -> 218.9209 | D42: =C42-(C42/$B$6+C42*$B$7+C42/$B$6*$B$8+C42*$B$9) -> 148.50134 | E42: 5 | F42: =C42*E42 -> 1094.6045 | G42: =D42*E42 -> 742.50672 | H42: =G42/G44 -> 0.14940251
A43: Chess Sets | B43: 119.5908 | C43: =B43*(1-$B$5) -> 101.65218 | D43: =C43-(C43/$B$6+C43*$B$7+C43/$B$6*$B$8+C43*$B$9) -> 68.954062 | E43: 3 | F43: =C43*E43 -> 304.95654 | G43: =D43*E43 -> 206.86219 | H43: =G43/G44 -> 0.041623503
A44: TOTAL MIX | E44: =SUM(E38:E43) -> 100 | F44: =SUM(F38:F43) -> 7326.5467 | G44: =SUM(G38:G43) -> 4969.8409 | H44: 1
A46: Total Margin from this Mix | B46: =G44 -> 4969.8409
A47: Monthly Fixed Costs | B47: =$B$10 -> 4035
A48: Net Profit (margin - fixed) | B48: =G44-$B$10 -> 934.84088
A49: Avg Ticket per Item | B49: =F44/E44 -> 73.265467
A50: Avg TRUE Margin per Item | B50: =G44/E44 -> 49.698409
...
